Workbook
Name Slicer_department_name: #N/A
Name Slicer_employment_status: #N/A
Name Slicer_job_level: #N/A
Name Slicer_region: #N/A

Sheet Raw_data
A1: employee_id | B1: hire_date | C1: department_name | D1: business_unit | E1: region | F1: role_title | G1: job_family | H1: job_level | I1: employment_status | J1: started_at | K1: ended_at | L1: termination_type | M1: tenure_days | N1: age_band | O1: education_level | P1: commute_band | Q1: latest_review_score | R1: latest_review_outcome | S1: review_count | T1: base_salary
A2: E000001 | B2: 2025-05-05 | C2: Engineering | D2: Product & Technology | E2: NA | F2: Software Engineering Specialist | G2: engineering | H2: specialist | I2: active | J2: 2025-05-05 | M2: 240 | N2: 25-34 | O2: masters | P2: remote | Q2: 4 | R2: exceeds | S2: 1 | T2: 99500.00
A3: E000002 | B3: 2023-08-02 | C3: Data & Analytics | D3: Product & Technology | E3: NA | F3: Analytics Specialist | G3: analytics | H3: specialist | I3: active | J3: 2023-08-02 | M3: 882 | N3: 25-34 | O3: masters | P3: remote | Q3: 3 | R3: meets | S3: 2 | T3: 98000.00
A4: E000003 | B4: 2024-02-06 | C4: Product | D4: Product & Technology | E4: EMEA | F4: Product Management Associate | G4: product | H4: associate | I4: active | J4: 2024-02-06 | M4: 694 | N4: 25-34 | O4: masters | P4: 31+_km | Q4: 3 | R4: meets | S4: 2 | T4: 60000.00
A5: E000004 | B5: 2024-11-07 | C5: Design | D5: Product & Technology | E5: EMEA | F5: Product Design Senior Specialist | G5: design | H5: senior | I5: terminated | J5: 2024-11-07 | K5: 2025-05-28 | L5: voluntary | M5: 202 | N5: 35-44 | O5: masters | P5: remote | Q5: 2 | R5: needs_support | S5: 1 | T5: 132500.00
A6: E000005 | B6: 2023-12-14 | C6: Sales | D6: Revenue | E6: NA | F6: Account Associate | G6: sales | H6: associate | I6: active | J6: 2023-12-14 | M6: 748 | N6: 25-34 | O6: masters | P6: remote | Q6: 3 | R6: meets | S6: 2 | T6: 73500.00
A7: E000006 | B7: 2024-12-01 | C7: Customer Success | D7: Revenue | E7: EMEA | F7: Customer Success Specialist | G7: customer_success | H7: specialist | I7: active | J7: 2024-12-01 | M7: 395 | N7: 35-44 | O7: bachelors | P7: 6-15_km | Q7: 3 | R7: meets | S7: 1 | T7: 81500.00
A8: E000007 | B8: 2024-12-21 | C8: Marketing | D8: Revenue | E8: APAC | F8: Growth Marketing Specialist | G8: marketing | H8: specialist | I8: active | J8: 2024-12-21 | M8: 375 | N8: 25-34 | O8: masters | P8: remote | Q8: 2 | R8: needs_support | S8: 1 | T8: 95000.00
A9: E000008 | B9: 2024-07-24 | C9: Finance | D9: Corporate | E9: NA | F9: Financial Planning Senior Specialist | G9: finance | H9: senior | I9: terminated | J9: 2024-07-24 | K9: 2025-03-17 | L9: voluntary | M9: 236 | N9: 45-54 | O9: masters | P9: 31+_km | Q9: 4 | R9: exceeds | S9: 1 | T9: 103500.00
A10: E000009 | B10: 2023-05-20 | C10: People Operations | D10: Corporate | E10: EMEA | F10: People Operations Senior Specialist | G10: people | H10: senior | I10: active | J10: 2023-05-20 | M10: 956 | N10: 35-44 | O10: bachelors | P10: 31+_km | Q10: 2 | R10: needs_support | S10: 3 | T10: 136000.00
A11: E000010 | B11: 2024-04-15 | C11: Legal & Compliance | D11: Corporate | E11: NA | F11: Legal & Compliance Specialist | G11: legal | H11: specialist | I11: terminated | J11: 2024-04-15 | K11: 2025-10-11 | L11: retirement | M11: 544 | N11: 25-34 | O11: bachelors | P11: remote | Q11: 4 | R11: exceeds | S11: 1 | T11: 74000.00
A12: E000011 | B12: 2024-12-13 | C12: Supply Chain | D12: Operations | E12: APAC | F12: Supply Chain Senior Specialist | G12: supply_chain | H12: senior | I12: active | J12: 2024-12-13 | M12: 383 | N12: 25-34 | O12: bachelors | P12: 6-15_km | Q12: 1 | R12: needs_support | S12: 1 | T12: 118000.00
A13: E000012 | B13: 2025-08-13 | C13: Business Operations | D13: Operations | E13: LATAM | F13: Operations Specialist | G13: operations | H13: specialist | I13: active | J13: 2025-08-13 | M13: 140 | N13: 25-34 | O13: bachelors | P13: 6-15_km | Q13: None | S13: 0 | T13: 81000.00
A14: E000013 | B14: 2023-12-13 | C14: Engineering | D14: Product & Technology | E14: NA | F14: Software Engineering Specialist | G14: engineering | H14: specialist | I14: active | J14: 2023-12-13 | M14: 749 | N14: 35-44 | O14: bachelors | P14: 31+_km | Q14: 4 | R14: exceeds | S14: 2 | T14: 96000.00
A15: E000014 | B15: 2023-11-22 | C15: Data & Analytics | D15: Product & Technology | E15: NA | F15: Analytics Specialist | G15: analytics | H15: specialist | I15: active | J15: 2023-11-22 | M15: 770 | N15: 35-44 | O15: associate | P15: 6-15_km | Q15: 4 | R15: exceeds | S15: 2 | T15: 100000.00
A16: E000015 | B16: 2024-03-25 | C16: Product | D16: Product & Technology | E16: EMEA | F16: Analytics Senior Specialist | G16: analytics | H16: senior | I16: active | J16: 2024-03-25 | M16: 646 | N16: 45-54 | O16: masters | P16: 6-15_km | Q16: 2 | R16: needs_support | S16: 2 | T16: 110500.00
A17: E000016 | B17: 2024-10-07 | C17: Design | D17: Product & Technology | E17: EMEA | F17: Product Design Specialist | G17: design | H17: specialist | I17: active | J17: 2024-10-07 | M17: 450 | N17: 35-44 | O17: bachelors | P17: remote | Q17: 3 | R17: meets | S17: 1 | T17: 90500.00
A18: E000017 | B18: 2025-08-30 | C18: Sales | D18: Revenue | E18: NA | F18: Account Associate | G18: sales | H18: associate | I18: active | J18: 2025-08-30 | M18: 123 | N18: 25-34 | O18: masters | P18: 6-15_km | Q18: None | S18: 0 | T18: 58000.00
A19: E000018 | B19: 2024-04-05 | C19: Customer Success | D19: Revenue | E19: EMEA | F19: Customer Success Associate | G19: customer_success | H19: associate | I19: terminated | J19: 2024-04-05 | K19: 2025-01-13 | L19: voluntary | M19: 283 | N19: 45-54 | O19: high_school | P19: 31+_km | Q19: 3 | R19: meets | S19: 1 | T19: 59000.00
A20: E000019 | B20: 2023-10-23 | C20: Marketing | D20: Revenue | E20: APAC | F20: Analytics Senior Specialist | G20: analytics | H20: senior | I20: active | J20: 2023-10-23 | M20: 800 | N20: 35-44 | O20: bachelors | P20: 16-30_km | Q20: 3 | R20: meets | S20: 2 | T20: 127000.00
A21: E000020 | B21: 2024-12-08 | C21: Finance | D21: Corporate | E21: NA | F21: Analytics Lead | G21: analytics | H21: lead | I21: active | J21: 2024-12-08 | M21: 388 | N21: 25-34 | O21: bachelors | P21: 16-30_km | Q21: 3 | R21: meets | S21: 1 | T21: 135000.00
A22: E000021 | B22: 2025-04-08 | C22: People Operations | D22: Corporate | E22: EMEA | F22: People Operations Associate | G22: people | H22: associate | I22: active | J22: 2025-04-08 | M22: 267 | N22: 25-34 | O22: masters | P22: 6-15_km | Q22: 3 | R22: meets | S22: 1 | T22: 62000.00
A23: E000022 | B23: 2023-11-20 | C23: Legal & Compliance | D23: Corporate | E23: NA | F23: Operations Associate | G23: operations | H23: associate | I23: active | J23: 2023-11-20 | M23: 772 | N23: 45-54 | O23: masters | P23: 6-15_km | Q23: 3 | R23: meets | S23: 2 | T23: 61500.00
A24: E000023 | B24: 2024-07-28 | C24: Supply Chain | D24: Operations | E24: APAC | F24: Supply Chain Specialist | G24: supply_chain | H24: specialist | I24: active | J24: 2024-07-28 | M24: 521 | N24: 25-34 | O24: bachelors | P24: remote | Q24: 1 | R24: needs_support | S24: 1 | T24: 104500.00
A25: E000024 | B25: 2024-06-22 | C25: Business Operations | D25: Operations | E25: LATAM | F25: Operations Associate | G25: operations | H25: associate | I25: terminated | J25: 2024-06-22 | K25: 2025-03-15 | L25: voluntary | M25: 266 | N25: 45-54 | O25: bachelors | P25: remote | Q25: 3 | R25: meets | S25: 1 | T25: 65500.00
A26: E000025 | B26: 2024-08-28 | C26: Engineering | D26: Product & Technology | E26: NA | F26: Software Engineering Specialist | G26: engineering | H26: specialist | I26: active | J26: 2024-08-28 | M26: 490 | N26: 35-44 | O26: high_school | P26: 6-15_km | Q26: 5 | R26: outstanding | S26: 1 | T26: 85000.00
A27: E000026 | B27: 2025-04-03 | C27: Data & Analytics | D27: Product & Technology | E27: NA | F27: Software Engineering Senior Specialist | G27: engineering | H27: senior | I27: active | J27: 2025-04-03 | M27: 272 | N27: 18-24 | O27: masters | P27: 6-15_km | Q27: 4 | R27: exceeds | S27: 1 | T27: 140000.00
A28: E000027 | B28: 2023-06-27 | C28: Product | D28: Product & Technology | E28: EMEA | F28: Analytics Specialist | G28: analytics | H28: specialist | I28: active | J28: 2023-06-27 | M28: 918 | N28: 25-34 | O28: high_school | P28: 6-15_km | Q28: 3 | R28: meets | S28: 3 | T28: 78500.00
A29: E000028 | B29: 2025-08-20 | C29: Design | D29: Product & Technology | E29: EMEA | F29: Product Design Senior Specialist | G29: design | H29: senior | I29: active | J29: 2025-08-20 | M29: 133 | N29: 25-34 | O29: masters | P29: remote | Q29: None | S29: 0 | T29: 140500.00
A30: E000029 | B30: 2024-06-02 | C30: Sales | D30: Revenue | E30: NA | F30: Account Associate | G30: sales | H30: associate | I30: active | J30: 2024-06-02 | M30: 577 | N30: 35-44 | O30: masters | P30: 6-15_km | Q30: 3 | R30: meets | S30: 2 | T30: 62000.00
A31: E000030 | B31: 2023-10-26 | C31: Customer Success | D31: Revenue | E31: EMEA | F31: Customer Success Specialist | G31: customer_success | H31: specialist | I31: active | J31: 2023-10-26 | M31: 797 | N31: 35-44 | O31: associate | P31: remote | Q31: 4 | R31: exceeds | S31: 2 | T31: 77000.00
A32: E000031 | B32: 2025-01-01 | C32: Marketing | D32: Revenue | E32: APAC | F32: Growth Marketing Specialist | G32: marketing | H32: specialist | I32: active | J32: 2025-01-01 | M32: 364 | N32: 35-44 | O32: bachelors | P32: 31+_km | Q32: 4 | R32: exceeds | S32: 1 | T32: 89500.00
A33: E000032 | B33: 2023-03-11 | C33: Finance | D33: Corporate | E33: NA | F33: Financial Planning Associate | G33: finance | H33: associate | I33: active | J33: 2023-03-11 | M33: 1026 | N33: 18-24 | O33: masters | P33: 6-15_km | Q33: 2 | R33: needs_support | S33: 3 | T33: 63000.00
A34: E000033 | B34: 2024-09-08 | C34: People Operations | D34: Corporate | E34: EMEA | F34: People Operations Specialist | G34: people | H34: specialist | I34: active | J34: 2024-09-08 | M34: 479 | N34: 35-44 | O34: high_school | P34: 6-15_km | Q34: 2 | R34: needs_support | S34: 1 | T34: 72500.00
A35: E000034 | B35: 2025-08-04 | C35: Legal & Compliance | D35: Corporate | E35: NA | F35: Legal & Compliance Specialist | G35: legal | H35: specialist | I35: active | J35: 2025-08-04 | M35: 149 | N35: 18-24 | O35: associate | P35: 0-5_km | Q35: None | S35: 0 | T35: 77500.00
A36: E000035 | B36: 2025-05-17 | C36: Supply Chain | D36: Operations | E36: APAC | F36: Supply Chain Associate | G36: supply_chain | H36: associate | I36: active | J36: 2025-05-17 | M36: 228 | N36: 18-24 | O36: masters | P36: 16-30_km | Q36: 4 | R36: exceeds | S36: 1 | T36: 62000.00
A37: E000036 | B37: 2024-02-03 | C37: Business Operations | D37: Operations | E37: LATAM | F37: Operations Associate | G37: operations | H37: associate | I37: active | J37: 2024-02-03 | M37: 697 | N37: 25-34 | O37: bachelors | P37: 0-5_km | Q37: 3 | R37: meets | S37: 2 | T37: 56000.00
A38: E000037 | B38: 2023-01-15 | C38: Engineering | D38: Product & Technology | E38: NA | F38: Analytics Associate | G38: analytics | H38: associate | I38: active | J38: 2023-01-15 | M38: 1081 | N38: 25-34 | O38: high_school | P38: 31+_km | Q38: 4 | R38: exceeds | S38: 3 | T38: 76500.00
A39: E000038 | B39: 2023-02-14 | C39: Data & Analytics | D39: Product & Technology | E39: NA | F39: Analytics Specialist | G39: analytics | H39: specialist | I39: active | J39: 2023-02-14 | M39: 1051 | N39: 55-64 | O39: masters | P39: 0-5_km | Q39: 3 | R39: meets | S39: 3 | T39: 95000.00
A40: E000039 | B40: 2023-09-19 | C40: Product | D40: Product & Technology | E40: EMEA | F40: Product Management Associate | G40: product | H40: associate | I40: active | J40: 2023-09-19 | M40: 834 | N40: 25-34 | O40: associate | P40: remote | Q40: 3 | R40: meets | S40: 2 | T40: 75500.00
...

Sheet Clean_data
A1: employee_id | B1: hire_date | C1: department_name | D1: business_unit | E1: region | F1: role_title | G1: job_family | H1: job_level | I1: employment_status | J1: started_at | K1: ended_at | L1: termination_type | M1: tenure_days | N1: age_band | O1: education_level | P1: commute_band | Q1: latest_review_score | R1: latest_review_outcome | S1: review_count | T1: base_salary | U1: Review_status | V1: Review_Outcome_Clean | W1: Attrition_Flag | X1: Attrition_Status | Y1: Tenure_Years | Z1: Tenure_Band | AA1: Salary_Band
A2: E000001 | B2: 45782 | C2: Engineering | D2: Product & Technology | E2: NA | F2: Software Engineering Specialist | G2: engineering | H2: specialist | I2: active | J2: 45782 | M2: 240 | N2: 25-34 | O2: masters | P2: remote | Q2: 4 | R2: exceeds | S2: 1 | T2: 99500 | U2: =IF(LOWER(TRIM(Q2&""))="none","Not Reviewed","Reviewed") -> Reviewed | V2: =IF(OR(Q2="none",R2=""),"Not Reviewed",R2) -> exceeds | W2: =IF(I2="terminated",1,0) -> 0 | X2: =IF(I2="terminated","Attrited","Active") -> Active | Y2: =M2/365 -> 0.65753425 | Z2: =IF(Y2<1,"<1 Year",IF(Y2<2,"1–2 Years",IF(Y2<3,"2–3 Years","3+ Years"))) -> <1 Year | AA2: =IF(T2<70000,"<70K",IF(T2<100000,"70K–99K",IF(T2<130000,"100K–129K","130K+"))) -> 70K–99K
A3: E000002 | B3: 45140 | C3: Data & Analytics | D3: Product & Technology | E3: NA | F3: Analytics Specialist | G3: analytics | H3: specialist | I3: active | J3: 45140 | M3: 882 | N3: 25-34 | O3: masters | P3: remote | Q3: 3 | R3: meets | S3: 2 | T3: 98000 | U3: =IF(LOWER(TRIM(Q3&""))="none","Not Reviewed","Reviewed") -> Reviewed | V3: =IF(OR(Q3="none",R3=""),"Not Reviewed",R3) -> meets | W3: =IF(I3="terminated",1,0) -> 0 | X3: =IF(I3="terminated","Attrited","Active") -> Active | Y3: =M3/365 -> 2.4164384 | Z3: =IF(Y3<1,"<1 Year",IF(Y3<2,"1–2 Years",IF(Y3<3,"2–3 Years","3+ Years"))) -> 2–3 Years | AA3: =IF(T3<70000,"<70K",IF(T3<100000,"70K–99K",IF(T3<130000,"100K–129K","130K+"))) -> 70K–99K
A4: E000003 | B4: 45328 | C4: Product | D4: Product & Technology | E4: EMEA | F4: Product Management Associate | G4: product | H4: associate | I4: active | J4: 45328 | M4: 694 | N4: 25-34 | O4: masters | P4: 31+_km | Q4: 3 | R4: meets | S4: 2 | T4: 60000 | U4: =IF(LOWER(TRIM(Q4&""))="none","Not Reviewed","Reviewed") -> Reviewed | V4: =IF(OR(Q4="none",R4=""),"Not Reviewed",R4) -> meets | W4: =IF(I4="terminated",1,0) -> 0 | X4: =IF(I4="terminated","Attrited","Active") -> Active | Y4: =M4/365 -> 1.9013699 | Z4: =IF(Y4<1,"<1 Year",IF(Y4<2,"1–2 Years",IF(Y4<3,"2–3 Years","3+ Years"))) -> 1–2 Years | AA4: =IF(T4<70000,"<70K",IF(T4<100000,"70K–99K",IF(T4<130000,"100K–129K","130K+"))) -> <70K
A5: E000004 | B5: 45603 | C5: Design | D5: Product & Technology | E5: EMEA | F5: Product Design Senior Specialist | G5: design | H5: senior | I5: terminated | J5: 45603 | K5: 45805 | L5: voluntary | M5: 202 | N5: 35-44 | O5: masters | P5: remote | Q5: 2 | R5: needs_support | S5: 1 | T5: 132500 | U5: =IF(LOWER(TRIM(Q5&""))="none","Not Reviewed","Reviewed") -> Reviewed | V5: =IF(OR(Q5="none",R5=""),"Not Reviewed",R5) -> needs_support | W5: =IF(I5="terminated",1,0) -> 1 | X5: =IF(I5="terminated","Attrited","Active") -> Attrited | Y5: =M5/365 -> 0.55342466 | Z5: =IF(Y5<1,"<1 Year",IF(Y5<2,"1–2 Years",IF(Y5<3,"2–3 Years","3+ Years"))) -> <1 Year | AA5: =IF(T5<70000,"<70K",IF(T5<100000,"70K–99K",IF(T5<130000,"100K–129K","130K+"))) -> 130K+
A6: E000005 | B6: 45274 | C6: Sales | D6: Revenue | E6: NA | F6: Account Associate | G6: sales | H6: associate | I6: active | J6: 45274 | M6: 748 | N6: 25-34 | O6: masters | P6: remote | Q6: 3 | R6: meets | S6: 2 | T6: 73500 | U6: =IF(LOWER(TRIM(Q6&""))="none","Not Reviewed","Reviewed") -> Reviewed | V6: =IF(OR(Q6="none",R6=""),"Not Reviewed",R6) -> meets | W6: =IF(I6="terminated",1,0) -> 0 | X6: =IF(I6="terminated","Attrited","Active") -> Active | Y6: =M6/365 -> 2.0493151 | Z6: =IF(Y6<1,"<1 Year",IF(Y6<2,"1–2 Years",IF(Y6<3,"2–3 Years","3+ Years"))) -> 2–3 Years | AA6: =IF(T6<70000,"<70K",IF(T6<100000,"70K–99K",IF(T6<130000,"100K–129K","130K+"))) -> 70K–99K
A7: E000006 | B7: 45627 | C7: Customer Success | D7: Revenue | E7: EMEA | F7: Customer Success Specialist | G7: customer_success | H7: specialist | I7: active | J7: 45627 | M7: 395 | N7: 35-44 | O7: bachelors | P7: 6-15_km | Q7: 3 | R7: meets | S7: 1 | T7: 81500 | U7: =IF(LOWER(TRIM(Q7&""))="none","Not Reviewed","Reviewed") -> Reviewed | V7: =IF(OR(Q7="none",R7=""),"Not Reviewed",R7) -> meets | W7: =IF(I7="terminated",1,0) -> 0 | X7: =IF(I7="terminated","Attrited","Active") -> Active | Y7: =M7/365 -> 1.0821918 | Z7: =IF(Y7<1,"<1 Year",IF(Y7<2,"1–2 Years",IF(Y7<3,"2–3 Years","3+ Years"))) -> 1–2 Years | AA7: =IF(T7<70000,"<70K",IF(T7<100000,"70K–99K",IF(T7<130000,"100K–129K","130K+"))) -> 70K–99K
A8: E000007 | B8: 45647 | C8: Marketing | D8: Revenue | E8: APAC | F8: Growth Marketing Specialist | G8: marketing | H8: specialist | I8: active | J8: 45647 | M8: 375 | N8: 25-34 | O8: masters | P8: remote | Q8: 2 | R8: needs_support | S8: 1 | T8: 95000 | U8: =IF(LOWER(TRIM(Q8&""))="none","Not Reviewed","Reviewed") -> Reviewed | V8: =IF(OR(Q8="none",R8=""),"Not Reviewed",R8) -> needs_support | W8: =IF(I8="terminated",1,0) -> 0 | X8: =IF(I8="terminated","Attrited","Active") -> Active | Y8: =M8/365 -> 1.0273973 | Z8: =IF(Y8<1,"<1 Year",IF(Y8<2,"1–2 Years",IF(Y8<3,"2–3 Years","3+ Years"))) -> 1–2 Years | AA8: =IF(T8<70000,"<70K",IF(T8<100000,"70K–99K",IF(T8<130000,"100K–129K","130K+"))) -> 70K–99K
A9: E000008 | B9: 45497 | C9: Finance | D9: Corporate | E9: NA | F9: Financial Planning Senior Specialist | G9: finance | H9: senior | I9: terminated | J9: 45497 | K9: 45733 | L9: voluntary | M9: 236 | N9: 45-54 | O9: masters | P9: 31+_km | Q9: 4 | R9: exceeds | S9: 1 | T9: 103500 | U9: =IF(LOWER(TRIM(Q9&""))="none","Not Reviewed","Reviewed") -> Reviewed | V9: =IF(OR(Q9="none",R9=""),"Not Reviewed",R9) -> exceeds | W9: =IF(I9="terminated",1,0) -> 1 | X9: =IF(I9="terminated","Attrited","Active") -> Attrited | Y9: =M9/365 -> 0.64657534 | Z9: =IF(Y9<1,"<1 Year",IF(Y9<2,"1–2 Years",IF(Y9<3,"2–3 Years","3+ Years"))) -> <1 Year | AA9: =IF(T9<70000,"<70K",IF(T9<100000,"70K–99K",IF(T9<130000,"100K–129K","130K+"))) -> 100K–129K
A10: E000009 | B10: 45066 | C10: People Operations | D10: Corporate | E10: EMEA | F10: People Operations Senior Specialist | G10: people | H10: senior | I10: active | J10: 45066 | M10: 956 | N10: 35-44 | O10: bachelors | P10: 31+_km | Q10: 2 | R10: needs_support | S10: 3 | T10: 136000 | U10: =IF(LOWER(TRIM(Q10&""))="none","Not Reviewed","Reviewed") -> Reviewed | V10: =IF(OR(Q10="none",R10=""),"Not Reviewed",R10) -> needs_support | W10: =IF(I10="terminated",1,0) -> 0 | X10: =IF(I10="terminated","Attrited","Active") -> Active | Y10: =M10/365 -> 2.6191781 | Z10: =IF(Y10<1,"<1 Year",IF(Y10<2,"1–2 Years",IF(Y10<3,"2–3 Years","3+ Years"))) -> 2–3 Years | AA10: =IF(T10<70000,"<70K",IF(T10<100000,"70K–99K",IF(T10<130000,"100K–129K","130K+"))) -> 130K+
A11: E000010 | B11: 45397 | C11: Legal & Compliance | D11: Corporate | E11: NA | F11: Legal & Compliance Specialist | G11: legal | H11: specialist | I11: terminated | J11: 45397 | K11: 45941 | L11: retirement | M11: 544 | N11: 25-34 | O11: bachelors | P11: remote | Q11: 4 | R11: exceeds | S11: 1 | T11: 74000 | U11: =IF(LOWER(TRIM(Q11&""))="none","Not Reviewed","Reviewed") -> Reviewed | V11: =IF(OR(Q11="none",R11=""),"Not Reviewed",R11) -> exceeds | W11: =IF(I11="terminated",1,0) -> 1 | X11: =IF(I11="terminated","Attrited","Active") -> Attrited | Y11: =M11/365 -> 1.490411 | Z11: =IF(Y11<1,"<1 Year",IF(Y11<2,"1–2 Years",IF(Y11<3,"2–3 Years","3+ Years"))) -> 1–2 Years | AA11: =IF(T11<70000,"<70K",IF(T11<100000,"70K–99K",IF(T11<130000,"100K–129K","130K+"))) -> 70K–99K
A12: E000011 | B12: 45639 | C12: Supply Chain | D12: Operations | E12: APAC | F12: Supply Chain Senior Specialist | G12: supply_chain | H12: senior | I12: active | J12: 45639 | M12: 383 | N12: 25-34 | O12: bachelors | P12: 6-15_km | Q12: 1 | R12: needs_support | S12: 1 | T12: 118000 | U12: =IF(LOWER(TRIM(Q12&""))="none","Not Reviewed","Reviewed") -> Reviewed | V12: =IF(OR(Q12="none",R12=""),"Not Reviewed",R12) -> needs_support | W12: =IF(I12="terminated",1,0) -> 0 | X12: =IF(I12="terminated","Attrited","Active") -> Active | Y12: =M12/365 -> 1.0493151 | Z12: =IF(Y12<1,"<1 Year",IF(Y12<2,"1–2 Years",IF(Y12<3,"2–3 Years","3+ Years"))) -> 1–2 Years | AA12: =IF(T12<70000,"<70K",IF(T12<100000,"70K–99K",IF(T12<130000,"100K–129K","130K+"))) -> 100K–129K
A13: E000012 | B13: 45882 | C13: Business Operations | D13: Operations | E13: LATAM | F13: Operations Specialist | G13: operations | H13: specialist | I13: active | J13: 45882 | M13: 140 | N13: 25-34 | O13: bachelors | P13: 6-15_km | Q13: None | S13: 0 | T13: 81000 | U13: =IF(LOWER(TRIM(Q13&""))="none","Not Reviewed","Reviewed") -> Not Reviewed | V13: =IF(OR(Q13="none",R13=""),"Not Reviewed",R13) -> Not Reviewed | W13: =IF(I13="terminated",1,0) -> 0 | X13: =IF(I13="terminated","Attrited","Active") -> Active | Y13: =M13/365 -> 0.38356164 | Z13: =IF(Y13<1,"<1 Year",IF(Y13<2,"1–2 Years",IF(Y13<3,"2–3 Years","3+ Years"))) -> <1 Year | AA13: =IF(T13<70000,"<70K",IF(T13<100000,"70K–99K",IF(T13<130000,"100K–129K","130K+"))) -> 70K–99K
A14: E000013 | B14: 45273 | C14: Engineering | D14: Product & Technology | E14: NA | F14: Software Engineering Specialist | G14: engineering | H14: specialist | I14: active | J14: 45273 | M14: 749 | N14: 35-44 | O14: bachelors | P14: 31+_km | Q14: 4 | R14: exceeds | S14: 2 | T14: 96000 | U14: =IF(LOWER(TRIM(Q14&""))="none","Not Reviewed","Reviewed") -> Reviewed | V14: =IF(OR(Q14="none",R14=""),"Not Reviewed",R14) -> exceeds | W14: =IF(I14="terminated",1,0) -> 0 | X14: =IF(I14="terminated","Attrited","Active") -> Active | Y14: =M14/365 -> 2.0520548 | Z14: =IF(Y14<1,"<1 Year",IF(Y14<2,"1–2 Years",IF(Y14<3,"2–3 Years","3+ Years"))) -> 2–3 Years | AA14: =IF(T14<70000,"<70K",IF(T14<100000,"70K–99K",IF(T14<130000,"100K–129K","130K+"))) -> 70K–99K
A15: E000014 | B15: 45252 | C15: Data & Analytics | D15: Product & Technology | E15: NA | F15: Analytics Specialist | G15: analytics | H15: specialist | I15: active | J15: 45252 | M15: 770 | N15: 35-44 | O15: associate | P15: 6-15_km | Q15: 4 | R15: exceeds | S15: 2 | T15: 100000 | U15: =IF(LOWER(TRIM(Q15&""))="none","Not Reviewed","Reviewed") -> Reviewed | V15: =IF(OR(Q15="none",R15=""),"Not Reviewed",R15) -> exceeds | W15: =IF(I15="terminated",1,0) -> 0 | X15: =IF(I15="terminated","Attrited","Active") -> Active | Y15: =M15/365 -> 2.109589 | Z15: =IF(Y15<1,"<1 Year",IF(Y15<2,"1–2 Years",IF(Y15<3,"2–3 Years","3+ Years"))) -> 2–3 Years | AA15: =IF(T15<70000,"<70K",IF(T15<100000,"70K–99K",IF(T15<130000,"100K–129K","130K+"))) -> 100K–129K
A16: E000015 | B16: 45376 | C16: Product | D16: Product & Technology | E16: EMEA | F16: Analytics Senior Specialist | G16: analytics | H16: senior | I16: active | J16: 45376 | M16: 646 | N16: 45-54 | O16: masters | P16: 6-15_km | Q16: 2 | R16: needs_support | S16: 2 | T16: 110500 | U16: =IF(LOWER(TRIM(Q16&""))="none","Not Reviewed","Reviewed") -> Reviewed | V16: =IF(OR(Q16="none",R16=""),"Not Reviewed",R16) -> needs_support | W16: =IF(I16="terminated",1,0) -> 0 | X16: =IF(I16="terminated","Attrited","Active") -> Active | Y16: =M16/365 -> 1.769863 | Z16: =IF(Y16<1,"<1 Year",IF(Y16<2,"1–2 Years",IF(Y16<3,"2–3 Years","3+ Years"))) -> 1–2 Years | AA16: =IF(T16<70000,"<70K",IF(T16<100000,"70K–99K",IF(T16<130000,"100K–129K","130K+"))) -> 100K–129K
A17: E000016 | B17: 45572 | C17: Design | D17: Product & Technology | E17: EMEA | F17: Product Design Specialist | G17: design | H17: specialist | I17: active | J17: 45572 | M17: 450 | N17: 35-44 | O17: bachelors | P17: remote | Q17: 3 | R17: meets | S17: 1 | T17: 90500 | U17: =IF(LOWER(TRIM(Q17&""))="none","Not Reviewed","Reviewed") -> Reviewed | V17: =IF(OR(Q17="none",R17=""),"Not Reviewed",R17) -> meets | W17: =IF(I17="terminated",1,0) -> 0 | X17: =IF(I17="terminated","Attrited","Active") -> Active | Y17: =M17/365 -> 1.2328767 | Z17: =IF(Y17<1,"<1 Year",IF(Y17<2,"1–2 Years",IF(Y17<3,"2–3 Years","3+ Years"))) -> 1–2 Years | AA17: =IF(T17<70000,"<70K",IF(T17<100000,"70K–99K",IF(T17<130000,"100K–129K","130K+"))) -> 70K–99K
A18: E000017 | B18: 45899 | C18: Sales | D18: Revenue | E18: NA | F18: Account Associate | G18: sales | H18: associate | I18: active | J18: 45899 | M18: 123 | N18: 25-34 | O18: masters | P18: 6-15_km | Q18: None | S18: 0 | T18: 58000 | U18: =IF(LOWER(TRIM(Q18&""))="none","Not Reviewed","Reviewed") -> Not Reviewed | V18: =IF(OR(Q18="none",R18=""),"Not Reviewed",R18) -> Not Reviewed | W18: =IF(I18="terminated",1,0) -> 0 | X18: =IF(I18="terminated","Attrited","Active") -> Active | Y18: =M18/365 -> 0.3369863 | Z18: =IF(Y18<1,"<1 Year",IF(Y18<2,"1–2 Years",IF(Y18<3,"2–3 Years","3+ Years"))) -> <1 Year | AA18: =IF(T18<70000,"<70K",IF(T18<100000,"70K–99K",IF(T18<130000,"100K–129K","130K+"))) -> <70K
A19: E000018 | B19: 45387 | C19: Customer Success | D19: Revenue | E19: EMEA | F19: Customer Success Associate | G19: customer_success | H19: associate | I19: terminated | J19: 45387 | K19: 45670 | L19: voluntary | M19: 283 | N19: 45-54 | O19: high_school | P19: 31+_km | Q19: 3 | R19: meets | S19: 1 | T19: 59000 | U19: =IF(LOWER(TRIM(Q19&""))="none","Not Reviewed","Reviewed") -> Reviewed | V19: =IF(OR(Q19="none",R19=""),"Not Reviewed",R19) -> meets | W19: =IF(I19="terminated",1,0) -> 1 | X19: =IF(I19="terminated","Attrited","Active") -> Attrited | Y19: =M19/365 -> 0.77534247 | Z19: =IF(Y19<1,"<1 Year",IF(Y19<2,"1–2 Years",IF(Y19<3,"2–3 Years","3+ Years"))) -> <1 Year | AA19: =IF(T19<70000,"<70K",IF(T19<100000,"70K–99K",IF(T19<130000,"100K–129K","130K+"))) -> <70K
A20: E000019 | B20: 45222 | C20: Marketing | D20: Revenue | E20: APAC | F20: Analytics Senior Specialist | G20: analytics | H20: senior | I20: active | J20: 45222 | M20: 800 | N20: 35-44 | O20: bachelors | P20: 16-30_km | Q20: 3 | R20: meets | S20: 2 | T20: 127000 | U20: =IF(LOWER(TRIM(Q20&""))="none","Not Reviewed","Reviewed") -> Reviewed | V20: =IF(OR(Q20="none",R20=""),"Not Reviewed",R20) -> meets | W20: =IF(I20="terminated",1,0) -> 0 | X20: =IF(I20="terminated","Attrited","Active") -> Active | Y20: =M20/365 -> 2.1917808 | Z20: =IF(Y20<1,"<1 Year",IF(Y20<2,"1–2 Years",IF(Y20<3,"2–3 Years","3+ Years"))) -> 2–3 Years | AA20: =IF(T20<70000,"<70K",IF(T20<100000,"70K–99K",IF(T20<130000,"100K–129K","130K+"))) -> 100K–129K
A21: E000020 | B21: 45634 | C21: Finance | D21: Corporate | E21: NA | F21: Analytics Lead | G21: analytics | H21: lead | I21: active | J21: 45634 | M21: 388 | N21: 25-34 | O21: bachelors | P21: 16-30_km | Q21: 3 | R21: meets | S21: 1 | T21: 135000 | U21: =IF(LOWER(TRIM(Q21&""))="none","Not Reviewed","Reviewed") -> Reviewed | V21: =IF(OR(Q21="none",R21=""),"Not Reviewed",R21) -> meets | W21: =IF(I21="terminated",1,0) -> 0 | X21: =IF(I21="terminated","Attrited","Active") -> Active | Y21: =M21/365 -> 1.0630137 | Z21: =IF(Y21<1,"<1 Year",IF(Y21<2,"1–2 Years",IF(Y21<3,"2–3 Years","3+ Years"))) -> 1–2 Years | AA21: =IF(T21<70000,"<70K",IF(T21<100000,"70K–99K",IF(T21<130000,"100K–129K","130K+"))) -> 130K+
A22: E000021 | B22: 45755 | C22: People Operations | D22: Corporate | E22: EMEA | F22: People Operations Associate | G22: people | H22: associate | I22: active | J22: 45755 | M22: 267 | N22: 25-34 | O22: masters | P22: 6-15_km | Q22: 3 | R22: meets | S22: 1 | T22: 62000 | U22: =IF(LOWER(TRIM(Q22&""))="none","Not Reviewed","Reviewed") -> Reviewed | V22: =IF(OR(Q22="none",R22=""),"Not Reviewed",R22) -> meets | W22: =IF(I22="terminated",1,0) -> 0 | X22: =IF(I22="terminated","Attrited","Active") -> Active | Y22: =M22/365 -> 0.73150685 | Z22: =IF(Y22<1,"<1 Year",IF(Y22<2,"1–2 Years",IF(Y22<3,"2–3 Years","3+ Years"))) -> <1 Year | AA22: =IF(T22<70000,"<70K",IF(T22<100000,"70K–99K",IF(T22<130000,"100K–129K","130K+"))) -> <70K
A23: E000022 | B23: 45250 | C23: Legal & Compliance | D23: Corporate | E23: NA | F23: Operations Associate | G23: operations | H23: associate | I23: active | J23: 45250 | M23: 772 | N23: 45-54 | O23: masters | P23: 6-15_km | Q23: 3 | R23: meets | S23: 2 | T23: 61500 | U23: =IF(LOWER(TRIM(Q23&""))="none","Not Reviewed","Reviewed") -> Reviewed | V23: =IF(OR(Q23="none",R23=""),"Not Reviewed",R23) -> meets | W23: =IF(I23="terminated",1,0) -> 0 | X23: =IF(I23="terminated","Attrited","Active") -> Active | Y23: =M23/365 -> 2.1150685 | Z23: =IF(Y23<1,"<1 Year",IF(Y23<2,"1–2 Years",IF(Y23<3,"2–3 Years","3+ Years"))) -> 2–3 Years | AA23: =IF(T23<70000,"<70K",IF(T23<100000,"70K–99K",IF(T23<130000,"100K–129K","130K+"))) -> <70K
A24: E000023 | B24: 45501 | C24: Supply Chain | D24: Operations | E24: APAC | F24: Supply Chain Specialist | G24: supply_chain | H24: specialist | I24: active | J24: 45501 | M24: 521 | N24: 25-34 | O24: bachelors | P24: remote | Q24: 1 | R24: needs_support | S24: 1 | T24: 104500 | U24: =IF(LOWER(TRIM(Q24&""))="none","Not Reviewed","Reviewed") -> Reviewed | V24: =IF(OR(Q24="none",R24=""),"Not Reviewed",R24) -> needs_support | W24: =IF(I24="terminated",1,0) -> 0 | X24: =IF(I24="terminated","Attrited","Active") -> Active | Y24: =M24/365 -> 1.4273973 | Z24: =IF(Y24<1,"<1 Year",IF(Y24<2,"1–2 Years",IF(Y24<3,"2–3 Years","3+ Years"))) -> 1–2 Years | AA24: =IF(T24<70000,"<70K",IF(T24<100000,"70K–99K",IF(T24<130000,"100K–129K","130K+"))) -> 100K–129K
A25: E000024 | B25: 45465 | C25: Business Operations | D25: Operations | E25: LATAM | F25: Operations Associate | G25: operations | H25: associate | I25: terminated | J25: 45465 | K25: 45731 | L25: voluntary | M25: 266 | N25: 45-54 | O25: bachelors | P25: remote | Q25: 3 | R25: meets | S25: 1 | T25: 65500 | U25: =IF(LOWER(TRIM(Q25&""))="none","Not Reviewed","Reviewed") -> Reviewed | V25: =IF(OR(Q25="none",R25=""),"Not Reviewed",R25) -> meets | W25: =IF(I25="terminated",1,0) -> 1 | X25: =IF(I25="terminated","Attrited","Active") -> Attrited | Y25: =M25/365 -> 0.72876712 | Z25: =IF(Y25<1,"<1 Year",IF(Y25<2,"1–2 Years",IF(Y25<3,"2–3 Years","3+ Years"))) -> <1 Year | AA25: =IF(T25<70000,"<70K",IF(T25<100000,"70K–99K",IF(T25<130000,"100K–129K","130K+"))) -> <70K
A26: E000025 | B26: 45532 | C26: Engineering | D26: Product & Technology | E26: NA | F26: Software Engineering Specialist | G26: engineering | H26: specialist | I26: active | J26: 45532 | M26: 490 | N26: 35-44 | O26: high_school | P26: 6-15_km | Q26: 5 | R26: outstanding | S26: 1 | T26: 85000 | U26: =IF(LOWER(TRIM(Q26&""))="none","Not Reviewed","Reviewed") -> Reviewed | V26: =IF(OR(Q26="none",R26=""),"Not Reviewed",R26) -> outstanding | W26: =IF(I26="terminated",1,0) -> 0 | X26: =IF(I26="terminated","Attrited","Active") -> Active | Y26: =M26/365 -> 1.3424658 | Z26: =IF(Y26<1,"<1 Year",IF(Y26<2,"1–2 Years",IF(Y26<3,"2–3 Years","3+ Years"))) -> 1–2 Years | AA26: =IF(T26<70000,"<70K",IF(T26<100000,"70K–99K",IF(T26<130000,"100K–129K","130K+"))) -> 70K–99K
A27: E000026 | B27: 45750 | C27: Data & Analytics | D27: Product & Technology | E27: NA | F27: Software Engineering Senior Specialist | G27: engineering | H27: senior | I27: active | J27: 45750 | M27: 272 | N27: 18-24 | O27: masters | P27: 6-15_km | Q27: 4 | R27: exceeds | S27: 1 | T27: 140000 | U27: =IF(LOWER(TRIM(Q27&""))="none","Not Reviewed","Reviewed") -> Reviewed | V27: =IF(OR(Q27="none",R27=""),"Not Reviewed",R27) -> exceeds | W27: =IF(I27="terminated",1,0) -> 0 | X27: =IF(I27="terminated","Attrited","Active") -> Active | Y27: =M27/365 -> 0.74520548 | Z27: =IF(Y27<1,"<1 Year",IF(Y27<2,"1–2 Years",IF(Y27<3,"2–3 Years","3+ Years"))) -> <1 Year | AA27: =IF(T27<70000,"<70K",IF(T27<100000,"70K–99K",IF(T27<130000,"100K–129K","130K+"))) -> 130K+
A28: E000027 | B28: 45104 | C28: Product | D28: Product & Technology | E28: EMEA | F28: Analytics Specialist | G28: analytics | H28: specialist | I28: active | J28: 45104 | M28: 918 | N28: 25-34 | O28: high_school | P28: 6-15_km | Q28: 3 | R28: meets | S28: 3 | T28: 78500 | U28: =IF(LOWER(TRIM(Q28&""))="none","Not Reviewed","Reviewed") -> Reviewed | V28: =IF(OR(Q28="none",R28=""),"Not Reviewed",R28) -> meets | W28: =IF(I28="terminated",1,0) -> 0 | X28: =IF(I28="terminated","Attrited","Active") -> Active | Y28: =M28/365 -> 2.5150685 | Z28: =IF(Y28<1,"<1 Year",IF(Y28<2,"1–2 Years",IF(Y28<3,"2–3 Years","3+ Years"))) -> 2–3 Years | AA28: =IF(T28<70000,"<70K",IF(T28<100000,"70K–99K",IF(T28<130000,"100K–129K","130K+"))) -> 70K–99K
A29: E000028 | B29: 45889 | C29: Design | D29: Product & Technology | E29: EMEA | F29: Product Design Senior Specialist | G29: design | H29: senior | I29: active | J29: 45889 | M29: 133 | N29: 25-34 | O29: masters | P29: remote | Q29: None | S29: 0 | T29: 140500 | U29: =IF(LOWER(TRIM(Q29&""))="none","Not Reviewed","Reviewed") -> Not Reviewed | V29: =IF(OR(Q29="none",R29=""),"Not Reviewed",R29) -> Not Reviewed | W29: =IF(I29="terminated",1,0) -> 0 | X29: =IF(I29="terminated","Attrited","Active") -> Active | Y29: =M29/365 -> 0.36438356 | Z29: =IF(Y29<1,"<1 Year",IF(Y29<2,"1–2 Years",IF(Y29<3,"2–3 Years","3+ Years"))) -> <1 Year | AA29: =IF(T29<70000,"<70K",IF(T29<100000,"70K–99K",IF(T29<130000,"100K–129K","130K+"))) -> 130K+
A30: E000029 | B30: 45445 | C30: Sales | D30: Revenue | E30: NA | F30: Account Associate | G30: sales | H30: associate | I30: active | J30: 45445 | M30: 577 | N30: 35-44 | O30: masters | P30: 6-15_km | Q30: 3 | R30: meets | S30: 2 | T30: 62000 | U30: =IF(LOWER(TRIM(Q30&""))="none","Not Reviewed","Reviewed") -> Reviewed | V30: =IF(OR(Q30="none",R30=""),"Not Reviewed",R30) -> meets | W30: =IF(I30="terminated",1,0) -> 0 | X30: =IF(I30="terminated","Attrited","Active") -> Active | Y30: =M30/365 -> 1.5808219 | Z30: =IF(Y30<1,"<1 Year",IF(Y30<2,"1–2 Years",IF(Y30<3,"2–3 Years","3+ Years"))) -> 1–2 Years | AA30: =IF(T30<70000,"<70K",IF(T30<100000,"70K–99K",IF(T30<130000,"100K–129K","130K+"))) -> <70K
A31: E000030 | B31: 45225 | C31: Customer Success | D31: Revenue | E31: EMEA | F31: Customer Success Specialist | G31: customer_success | H31: specialist | I31: active | J31: 45225 | M31: 797 | N31: 35-44 | O31: associate | P31: remote | Q31: 4 | R31: exceeds | S31: 2 | T31: 77000 | U31: =IF(LOWER(TRIM(Q31&""))="none","Not Reviewed","Reviewed") -> Reviewed | V31: =IF(OR(Q31="none",R31=""),"Not Reviewed",R31) -> exceeds | W31: =IF(I31="terminated",1,0) -> 0 | X31: =IF(I31="terminated","Attrited","Active") -> Active | Y31: =M31/365 -> 2.1835616 | Z31: =IF(Y31<1,"<1 Year",IF(Y31<2,"1–2 Years",IF(Y31<3,"2–3 Years","3+ Years"))) -> 2–3 Years | AA31: =IF(T31<70000,"<70K",IF(T31<100000,"70K–99K",IF(T31<130000,"100K–129K","130K+"))) -> 70K–99K
A32: E000031 | B32: 45658 | C32: Marketing | D32: Revenue | E32: APAC | F32: Growth Marketing Specialist | G32: marketing | H32: specialist | I32: active | J32: 45658 | M32: 364 | N32: 35-44 | O32: bachelors | P32: 31+_km | Q32: 4 | R32: exceeds | S32: 1 | T32: 89500 | U32: =IF(LOWER(TRIM(Q32&""))="none","Not Reviewed","Reviewed") -> Reviewed | V32: =IF(OR(Q32="none",R32=""),"Not Reviewed",R32) -> exceeds | W32: =IF(I32="terminated",1,0) -> 0 | X32: =IF(I32="terminated","Attrited","Active") -> Active | Y32: =M32/365 -> 0.99726027 | Z32: =IF(Y32<1,"<1 Year",IF(Y32<2,"1–2 Years",IF(Y32<3,"2–3 Years","3+ Years"))) -> <1 Year | AA32: =IF(T32<70000,"<70K",IF(T32<100000,"70K–99K",IF(T32<130000,"100K–129K","130K+"))) -> 70K–99K
A33: E000032 | B33: 44996 | C33: Finance | D33: Corporate | E33: NA | F33: Financial Planning Associate | G33: finance | H33: associate | I33: active | J33: 44996 | M33: 1026 | N33: 18-24 | O33: masters | P33: 6-15_km | Q33: 2 | R33: needs_support | S33: 3 | T33: 63000 | U33: =IF(LOWER(TRIM(Q33&""))="none","Not Reviewed","Reviewed") -> Reviewed | V33: =IF(OR(Q33="none",R33=""),"Not Reviewed",R33) -> needs_support | W33: =IF(I33="terminated",1,0) -> 0 | X33: =IF(I33="terminated","Attrited","Active") -> Active | Y33: =M33/365 -> 2.8109589 | Z33: =IF(Y33<1,"<1 Year",IF(Y33<2,"1–2 Years",IF(Y33<3,"2–3 Years","3+ Years"))) -> 2–3 Years | AA33: =IF(T33<70000,"<70K",IF(T33<100000,"70K–99K",IF(T33<130000,"100K–129K","130K+"))) -> <70K
A34: E000033 | B34: 45543 | C34: People Operations | D34: Corporate | E34: EMEA | F34: People Operations Specialist | G34: people | H34: specialist | I34: active | J34: 45543 | M34: 479 | N34: 35-44 | O34: high_school | P34: 6-15_km | Q34: 2 | R34: needs_support | S34: 1 | T34: 72500 | U34: =IF(LOWER(TRIM(Q34&""))="none","Not Reviewed","Reviewed") -> Reviewed | V34: =IF(OR(Q34="none",R34=""),"Not Reviewed",R34) -> needs_support | W34: =IF(I34="terminated",1,0) -> 0 | X34: =IF(I34="terminated","Attrited","Active") -> Active | Y34: =M34/365 -> 1.3123288 | Z34: =IF(Y34<1,"<1 Year",IF(Y34<2,"1–2 Years",IF(Y34<3,"2–3 Years","3+ Years"))) -> 1–2 Years | AA34: =IF(T34<70000,"<70K",IF(T34<100000,"70K–99K",IF(T34<130000,"100K–129K","130K+"))) -> 70K–99K
A35: E000034 | B35: 45873 | C35: Legal & Compliance | D35: Corporate | E35: NA | F35: Legal & Compliance Specialist | G35: legal | H35: specialist | I35: active | J35: 45873 | M35: 149 | N35: 18-24 | O35: associate | P35: 0-5_km | Q35: None | S35: 0 | T35: 77500 | U35: =IF(LOWER(TRIM(Q35&""))="none","Not Reviewed","Reviewed") -> Not Reviewed | V35: =IF(OR(Q35="none",R35=""),"Not Reviewed",R35) -> Not Reviewed | W35: =IF(I35="terminated",1,0) -> 0 | X35: =IF(I35="terminated","Attrited","Active") -> Active | Y35: =M35/365 -> 0.40821918 | Z35: =IF(Y35<1,"<1 Year",IF(Y35<2,"1–2 Years",IF(Y35<3,"2–3 Years","3+ Years"))) -> <1 Year | AA35: =IF(T35<70000,"<70K",IF(T35<100000,"70K–99K",IF(T35<130000,"100K–129K","130K+"))) -> 70K–99K
A36: E000035 | B36: 45794 | C36: Supply Chain | D36: Operations | E36: APAC | F36: Supply Chain Associate | G36: supply_chain | H36: associate | I36: active | J36: 45794 | M36: 228 | N36: 18-24 | O36: masters | P36: 16-30_km | Q36: 4 | R36: exceeds | S36: 1 | T36: 62000 | U36: =IF(LOWER(TRIM(Q36&""))="none","Not Reviewed","Reviewed") -> Reviewed | V36: =IF(OR(Q36="none",R36=""),"Not Reviewed",R36) -> exceeds | W36: =IF(I36="terminated",1,0) -> 0 | X36: =IF(I36="terminated","Attrited","Active") -> Active | Y36: =M36/365 -> 0.62465753 | Z36: =IF(Y36<1,"<1 Year",IF(Y36<2,"1–2 Years",IF(Y36<3,"2–3 Years","3+ Years"))) -> <1 Year | AA36: =IF(T36<70000,"<70K",IF(T36<100000,"70K–99K",IF(T36<130000,"100K–129K","130K+"))) -> <70K
A37: E000036 | B37: 45325 | C37: Business Operations | D37: Operations | E37: LATAM | F37: Operations Associate | G37: operations | H37: associate | I37: active | J37: 45325 | M37: 697 | N37: 25-34 | O37: bachelors | P37: 0-5_km | Q37: 3 | R37: meets | S37: 2 | T37: 56000 | U37: =IF(LOWER(TRIM(Q37&""))="none","Not Reviewed","Reviewed") -> Reviewed | V37: =IF(OR(Q37="none",R37=""),"Not Reviewed",R37) -> meets | W37: =IF(I37="terminated",1,0) -> 0 | X37: =IF(I37="terminated","Attrited","Active") -> Active | Y37: =M37/365 -> 1.909589 | Z37: =IF(Y37<1,"<1 Year",IF(Y37<2,"1–2 Years",IF(Y37<3,"2–3 Years","3+ Years"))) -> 1–2 Years | AA37: =IF(T37<70000,"<70K",IF(T37<100000,"70K–99K",IF(T37<130000,"100K–129K","130K+"))) -> <70K
A38: E000037 | B38: 44941 | C38: Engineering | D38: Product & Technology | E38: NA | F38: Analytics Associate | G38: analytics | H38: associate | I38: active | J38: 44941 | M38: 1081 | N38: 25-34 | O38: high_school | P38: 31+_km | Q38: 4 | R38: exceeds | S38: 3 | T38: 76500 | U38: =IF(LOWER(TRIM(Q38&""))="none","Not Reviewed","Reviewed") -> Reviewed | V38: =IF(OR(Q38="none",R38=""),"Not Reviewed",R38) -> exceeds | W38: =IF(I38="terminated",1,0) -> 0 | X38: =IF(I38="terminated","Attrited","Active") -> Active | Y38: =M38/365 -> 2.9616438 | Z38: =IF(Y38<1,"<1 Year",IF(Y38<2,"1–2 Years",IF(Y38<3,"2–3 Years","3+ Years"))) -> 2–3 Years | AA38: =IF(T38<70000,"<70K",IF(T38<100000,"70K–99K",IF(T38<130000,"100K–129K","130K+"))) -> 70K–99K
A39: E000038 | B39: 44971 | C39: Data & Analytics | D39: Product & Technology | E39: NA | F39: Analytics Specialist | G39: analytics | H39: specialist | I39: active | J39: 44971 | M39: 1051 | N39: 55-64 | O39: masters | P39: 0-5_km | Q39: 3 | R39: meets | S39: 3 | T39: 95000 | U39: =IF(LOWER(TRIM(Q39&""))="none","Not Reviewed","Reviewed") -> Reviewed | V39: =IF(OR(Q39="none",R39=""),"Not Reviewed",R39) -> meets | W39: =IF(I39="terminated",1,0) -> 0 | X39: =IF(I39="terminated","Attrited","Active") -> Active | Y39: =M39/365 -> 2.8794521 | Z39: =IF(Y39<1,"<1 Year",IF(Y39<2,"1–2 Years",IF(Y39<3,"2–3 Years","3+ Years"))) -> 2–3 Years | AA39: =IF(T39<70000,"<70K",IF(T39<100000,"70K–99K",IF(T39<130000,"100K–129K","130K+"))) -> 70K–99K
A40: E000039 | B40: 45188 | C40: Product | D40: Product & Technology | E40: EMEA | F40: Product Management Associate | G40: product | H40: associate | I40: active | J40: 45188 | M40: 834 | N40: 25-34 | O40: associate | P40: remote | Q40: 3 | R40: meets | S40: 2 | T40: 75500 | U40: =IF(LOWER(TRIM(Q40&""))="none","Not Reviewed","Reviewed") -> Reviewed | V40: =IF(OR(Q40="none",R40=""),"Not Reviewed",R40) -> meets | W40: =IF(I40="terminated",1,0) -> 0 | X40: =IF(I40="terminated","Attrited","Active") -> Active | Y40: =M40/365 -> 2.2849315 | Z40: =IF(Y40<1,"<1 Year",IF(Y40<2,"1–2 Years",IF(Y40<3,"2–3 Years","3+ Years"))) -> 2–3 Years | AA40: =IF(T40<70000,"<70K",IF(T40<100000,"70K–99K",IF(T40<130000,"100K–129K","130K+"))) -> 70K–99K
...

Sheet Calculations
A1: CALCULATIONS
A2: Data Quality Formulas | D2: Businees Analysis Formulas
A3: Total employees | B3: =COUNTA(Clean_data!A2:A6001) -> 6000 | D3: Total Employees | E3: =COUNTA(Clean_data!A2:A6001) -> 6000
A4: Duplicate Employee IDs | B4: =COUNTA(Clean_data!A2:A6001)-COUNTA(_xlfn.UNIQUE(Clean_data!A2:A6001)) -> 0 | D4: Active Employees | E4: =COUNTIF(Clean_data!X2:X6001,"Active") -> 4975
A5: Missing Values Count | D5: Attrited Employees | E5: =COUNTIF(Clean_data!X2:X6001,"Attrited") -> 1025
A6: employee_id | B6: =COUNTBLANK(Clean_data!A2:A6001) -> 0 | D6: Attrition Rate | E6: =COUNTIF(Clean_data!X2:X6001,"Attrited")/COUNTA(Clean_data!A2:A6001) -> 0.17083333
A7: hire_date | B7: =COUNTBLANK(Clean_data!B2:B6001) -> 0 | D7: Average Salary | E7: =AVERAGE(Clean_data!T2:T6001) -> 90996.583
A8: department_name | B8: =COUNTBLANK(Clean_data!C2:C6001) -> 0 | D8: Minimum Salary | E8: =MIN(Clean_data!T2:T6001) -> 55000
A9: business_unit | B9: =COUNTBLANK(Clean_data!D2:D6001) -> 0 | D9: Maximum Salary | E9: =MAX(Clean_data!T2:T6001) -> 188000
A10: region | B10: =COUNTBLANK(Clean_data!A2:A6001) -> 0 | D10: Average Tenure | E10: =AVERAGE(Clean_data!Y2:Y6001) -> 1.5169037
A11: role_title | B11: =COUNTBLANK(Clean_data!E2:E6001) -> 0 | D11: Reviewed Employees | E11: =COUNTIF(Clean_data!U2:U6001,"Reviewed") -> 5219
A12: job_family | B12: =COUNTBLANK(Clean_data!F2:F6001) -> 0 | D12: Not Reviewed Employees | E12: =COUNTIF(Clean_data!U2:U6001,"Not Reviewed") -> 781
A13: job_level | B13: =COUNTBLANK(Clean_data!H2:H6001) -> 0
A14: employment_status | B14: =COUNTBLANK(Clean_data!I2:I6001) -> 0
A15: started_at | B15: =COUNTBLANK(Clean_data!J2:J6001) -> 0
A16: ended_at | B16: =COUNTBLANK(Clean_data!K2:K6001) -> 4975
A17: termination_type | B17: =COUNTBLANK(Clean_data!L2:L6001) -> 4975
A18: tenure_days | B18: =COUNTBLANK(Clean_data!M2:M6001) -> 0
A19: age_band | B19: =COUNTBLANK(Clean_data!N2:N6001) -> 0
A20: education_level | B20: =COUNTBLANK(Clean_data!O2:O6001) -> 0
A21: commute_band | B21: =COUNTBLANK(Clean_data!P2:P6001) -> 0
A22: latest_review_score | B22: =COUNTBLANK(Clean_data!Q2:Q6001) -> 0
A23: latest_review_outcome | B23: =COUNTBLANK(Clean_data!R2:R6001) -> 781
A24: review_count | B24: =COUNTBLANK(Clean_data!S2:S6001) -> 0
A25: base_salary | B25: =COUNTBLANK(Clean_data!T2:T6001) -> 0

Sheet PivotTables
A1: Attrition by Department | F1: Attrition Rate by Department | I1: Attrition by Job Level
A2: Department Name | F2: Department Name | G2: Average of Attrition_Flag | I2: Job Level
B3: Active | C3: Attrited | D3: Grand Total | F3: Business Operations | G3: 0.17 | J3: Active | K3: Attrited | L3: Grand Total
A4: Business Operations | B4: 415 | C4: 85 | D4: 500 | F4: Customer Success | G4: 0.188 | I4: associate | J4: 1732 | K4: 345 | L4: 2077
A5: Customer Success | B5: 406 | C5: 94 | D5: 500 | F5: Data & Analytics | G5: 0.172 | I5: lead | J5: 248 | K5: 41 | L5: 289
A6: Data & Analytics | B6: 414 | C6: 86 | D6: 500 | F6: Design | G6: 0.174 | I6: senior | J6: 1118 | K6: 230 | L6: 1348
A7: Design | B7: 413 | C7: 87 | D7: 500 | F7: Engineering | G7: 0.18 | I7: specialist | J7: 1877 | K7: 409 | L7: 2286
A8: Engineering | B8: 410 | C8: 90 | D8: 500 | F8: Finance | G8: 0.176 | I8: Grand Total | J8: 4975 | K8: 1025 | L8: 6000
A9: Finance | B9: 412 | C9: 88 | D9: 500 | F9: Legal & Compliance | G9: 0.148
A10: Legal & Compliance | B10: 426 | C10: 74 | D10: 500 | F10: Marketing | G10: 0.172 | I10: Attrition by Tenure
A11: Marketing | B11: 414 | C11: 86 | D11: 500 | F11: People Operations | G11: 0.15 | I11: Tenure Band
A12: People Operations | B12: 425 | C12: 75 | D12: 500 | F12: Product | G12: 0.16 | J12: Active | K12: Attrited | L12: Grand Total
A13: Product | B13: 420 | C13: 80 | D13: 500 | F13: Sales | G13: 0.188 | I13: <1 Year | J13: 1341 | K13: 625 | L13: 1966
A14: Sales | B14: 406 | C14: 94 | D14: 500 | F14: Supply Chain | G14: 0.172 | I14: 1–2 Years | J14: 1788 | K14: 318 | L14: 2106
A15: Supply Chain | B15: 414 | C15: 86 | D15: 500 | F15: Grand Total | G15: 0.17083333 | I15: 2–3 Years | J15: 1843 | K15: 82 | L15: 1925
A16: Grand Total | B16: 4975 | C16: 1025 | D16: 6000 | I16: 3+ Years | J16: 3 | L16: 3
I17: Grand Total | J17: 4975 | K17: 1025 | L17: 6000
A19: Attrition by Age Band | E19: Attrition by Education | I19: Attrition by Commute
A20: Age Band | B20: Count of employee_id | C20: Sum of Attrition_Flag | E20: Education Level | F20: Count of employee_id | G20: Sum of Attrition_Flag | I20: Commute Band | J20: Count of employee_id | K20: Sum of Attrition_Flag
A21: 18-24 | B21: 555 | C21: 102 | E21: associate | F21: 785 | G21: 137 | I21: 0-5_km | J21: 718 | K21: 119
A22: 25-34 | B22: 2368 | C22: 376 | E22: bachelors | F22: 2883 | G22: 482 | I22: 16-30_km | J22: 1308 | K22: 230
A23: 35-44 | B23: 1824 | C23: 325 | E23: high_school | F23: 512 | G23: 93 | I23: 31+_km | J23: 627 | K23: 112
A24: 45-54 | B24: 957 | C24: 179 | E24: masters | F24: 1510 | G24: 266 | I24: 6-15_km | J24: 1617 | K24: 260
A25: 55-64 | B25: 296 | C25: 43 | E25: professional | F25: 310 | G25: 47 | I25: remote | J25: 1730 | K25: 304
A26: Grand Total | B26: 6000 | C26: 1025 | E26: Grand Total | F26: 6000 | G26: 1025 | I26: Grand Total | J26: 6000 | K26: 1025
A29: Salary by Department | D29: Attrition by Salary Band | I29: Attrition by Region
A30: Department Name | B30: Average of base_salary | D30: Salary | I30: Regions
A31: Business Operations | B31: 89129 | E31: Active | F31: Attrited | G31: Grand Total | J31: Active | K31: Attrited | L31: Grand Total
A32: Customer Success | B32: 91380 | D32: <70K | E32: 1055 | F32: 221 | G32: 1276 | I32: APAC | J32: 828 | K32: 172 | L32: 1000
A33: Data & Analytics | B33: 91860 | D33: 100K–129K | E33: 999 | F33: 209 | G33: 1208 | I33: EMEA | J33: 1664 | K33: 336 | L33: 2000
A34: Design | B34: 90441 | D34: 130K+ | E34: 551 | F34: 110 | G34: 661 | I34: LATAM | J34: 415 | K34: 85 | L34: 500
A35: Engineering | B35: 91429 | D35: 70K–99K | E35: 2370 | F35: 485 | G35: 2855 | I35: NA | J35: 2068 | K35: 432 | L35: 2500
A36: Finance | B36: 90531 | D36: Grand Total | E36: 4975 | F36: 1025 | G36: 6000 | I36: Grand Total | J36: 4975 | K36: 1025 | L36: 6000
A37: Legal & Compliance | B37: 91131
A38: Marketing | B38: 90329 | D38: Review Status
A39: People Operations | B39: 91261 | D39: Review Status | E39: Count of employee_id
A40: Product | B40: 91393 | D40: Not Reviewed | E40: 781
A41: Sales | B41: 92253 | D41: Reviewed | E41: 5219
A42: Supply Chain | B42: 90822 | D42: Grand Total | E42: 6000
A43: Grand Total | B43: 90996.583

Sheet Dashboard
A1: EMPLOYEE WORKFORCE & ATTRITION ANALYSIS
B7: TOTAL EMPLOYEES | G7: ACTIVE EMPLOYEES | L7: ATTRITED EMPLOYEES | Q7: ATTRITION RATE | V7: AVERAGE SALARY
B9: =Calculations!E3 -> 6000 | G9: =Calculations!E4 -> 4975 | L9: =Calculations!E5 -> 1025 | Q9: =Calculations!E6 -> 0.17083333 | V9: =Calculations!E7 -> 90996.583

Sheet Insights
A1: EMPLOYEE WORKFORCE & ATTRITION — KEY INSIGHTS
A4: EXECUTIVE SUMMARY
A5: 1. Overall Workforce
A6: The organization has 6,000 employees, with 4,975 active employees and 1,025 attrited employees.
A8: 2. Overall Attrition
A9: The overall attrition rate is 17.1%, meaning approximately 17 out of every 100 employees have attrited.
A11: 3. Employee Reviews
A12: 5,219 employees have a recorded review score, while 781 employees have not been reviewed.
A14: 4. Department-Level Pattern
A15: Attrition varies across departments, with the highest attrition counts observed in Customer Success and Sales, while Legal & Compliance has the lowest attrition count.
A17: 5. Data Quality
A18: Employee IDs are unique and region values are complete. Review-related fields contain some missing or "none" values that were retained and classified as Not Reviewed.
A20: KEY MATRICS
B21: Total Employees | D21: =Calculations!E3 -> 6000
B22: Active Employees | D22: =Calculations!E4 -> 4975
B23: Attrited Employees | D23: =Calculations!E5 -> 1025
B24: Attrition Rate | D24: =Calculations!E6 -> 0.17083333
B25: Reviewed Employees | D25: =Calculations!E11 -> 5219
B26: Not Reviewed | D26: =Calculations!E12 -> 781
A28: ADD BUSINESS FINDINGS
A29: Department Attrition
A30: Customer Success and Sales each have 94 attrited employees, while Legal & Compliance has 74. The difference shows that attrition is not evenly distributed across departments.
A32: Tenure & Attrition
A33: Compare attrition across the tenure bands to identify whether employees earlier in their careers or longer-tenured employees show higher attrition counts.
A35: Salary & Attrition
A36: The salary-band analysis can be used to examine whether attrition is concentrated within particular compensation ranges.
A38: Review Coverage
A39: 781 employees are classified as Not Reviewed, representing about 13.0% of the workforce. This indicates an opportunity to improve review coverage.
A41: ANALYST RECOMMENDATIONS
A42: Monitor Department-Level Attrition
A43: Review attrition patterns in departments with higher attrition counts and investigate potential drivers through employee feedback and exit data.
... A69: Analyzed workforce size, attrition, employee reviews, department, region, job level, tenure and salary patterns.
